[2024-11-08T17:31:16.375+0000] {taskinstance.py:1157} INFO - Dependencies all met for dep_context=non-requeueable deps ti=<TaskInstance: daily_clothing_crawler.run_main_py manual__2024-11-08T17:31:15.692191+00:00 [queued]>
[2024-11-08T17:31:16.378+0000] {taskinstance.py:1157} INFO - Dependencies all met for dep_context=requeueable deps ti=<TaskInstance: daily_clothing_crawler.run_main_py manual__2024-11-08T17:31:15.692191+00:00 [queued]>
[2024-11-08T17:31:16.379+0000] {taskinstance.py:1359} INFO - Starting attempt 1 of 2
[2024-11-08T17:31:16.384+0000] {taskinstance.py:1380} INFO - Executing <Task(BashOperator): run_main_py> on 2024-11-08 17:31:15.692191+00:00
[2024-11-08T17:31:16.387+0000] {standard_task_runner.py:57} INFO - Started process 614 to run task
[2024-11-08T17:31:16.389+0000] {standard_task_runner.py:84} INFO - Running: ['***', 'tasks', 'run', 'daily_clothing_crawler', 'run_main_py', 'manual__2024-11-08T17:31:15.692191+00:00', '--job-id', '4', '--raw', '--subdir', 'DAGS_FOLDER/DAG.py', '--cfg-path', '/tmp/tmp4x0tpttv']
[2024-11-08T17:31:16.391+0000] {standard_task_runner.py:85} INFO - Job 4: Subtask run_main_py
[2024-11-08T17:31:16.416+0000] {task_command.py:415} INFO - Running <TaskInstance: daily_clothing_crawler.run_main_py manual__2024-11-08T17:31:15.692191+00:00 [running]> on host 58af73ec9de6
[2024-11-08T17:31:16.455+0000] {taskinstance.py:1660} INFO - Exporting env vars: AIRFLOW_CTX_DAG_OWNER='***' AIRFLOW_CTX_DAG_ID='daily_clothing_crawler' AIRFLOW_CTX_TASK_ID='run_main_py' AIRFLOW_CTX_EXECUTION_DATE='2024-11-08T17:31:15.692191+00:00' AIRFLOW_CTX_TRY_NUMBER='1' AIRFLOW_CTX_DAG_RUN_ID='manual__2024-11-08T17:31:15.692191+00:00'
[2024-11-08T17:31:16.456+0000] {subprocess.py:63} INFO - Tmp dir root location: /tmp
[2024-11-08T17:31:16.456+0000] {subprocess.py:75} INFO - Running command: ['/bin/bash', '-c', 'python3 app/main.py']
[2024-11-08T17:31:16.461+0000] {subprocess.py:86} INFO - Output:
[2024-11-08T17:31:16.513+0000] {subprocess.py:93} INFO - python3: can't open file 'app/main.py': [Errno 2] No such file or directory
[2024-11-08T17:31:16.514+0000] {subprocess.py:97} INFO - Command exited with return code 2
[2024-11-08T17:31:16.520+0000] {taskinstance.py:1935} ERROR - Task failed with exception
Traceback (most recent call last):
  File "/home/airflow/.local/lib/python3.8/site-packages/airflow/operators/bash.py", line 210, in execute
    raise AirflowException(
airflow.exceptions.AirflowException: Bash command failed. The command returned a non-zero exit code 2.
[2024-11-08T17:31:16.522+0000] {taskinstance.py:1398} INFO - Marking task as UP_FOR_RETRY. dag_id=daily_clothing_crawler, task_id=run_main_py, execution_date=20241108T173115, start_date=20241108T173116, end_date=20241108T173116
[2024-11-08T17:31:16.528+0000] {standard_task_runner.py:104} ERROR - Failed to execute job 4 for task run_main_py (Bash command failed. The command returned a non-zero exit code 2.; 614)
[2024-11-08T17:31:16.533+0000] {local_task_job_runner.py:228} INFO - Task exited with return code 1
[2024-11-08T17:31:16.541+0000] {taskinstance.py:2776} INFO - 0 downstream tasks scheduled from follow-on schedule check
