[2024-11-08T17:36:16.952+0000] {taskinstance.py:1157} INFO - Dependencies all met for dep_context=non-requeueable deps ti=<TaskInstance: daily_clothing_crawler.run_main_py manual__2024-11-08T17:31:15.692191+00:00 [queued]>
[2024-11-08T17:36:16.955+0000] {taskinstance.py:1157} INFO - Dependencies all met for dep_context=requeueable deps ti=<TaskInstance: daily_clothing_crawler.run_main_py manual__2024-11-08T17:31:15.692191+00:00 [queued]>
[2024-11-08T17:36:16.955+0000] {taskinstance.py:1359} INFO - Starting attempt 2 of 2
[2024-11-08T17:36:16.960+0000] {taskinstance.py:1380} INFO - Executing <Task(BashOperator): run_main_py> on 2024-11-08 17:31:15.692191+00:00
[2024-11-08T17:36:16.962+0000] {standard_task_runner.py:57} INFO - Started process 667 to run task
[2024-11-08T17:36:16.964+0000] {standard_task_runner.py:84} INFO - Running: ['***', 'tasks', 'run', 'daily_clothing_crawler', 'run_main_py', 'manual__2024-11-08T17:31:15.692191+00:00', '--job-id', '5', '--raw', '--subdir', 'DAGS_FOLDER/DAG.py', '--cfg-path', '/tmp/tmp6mqxyxr9']
[2024-11-08T17:36:16.966+0000] {standard_task_runner.py:85} INFO - Job 5: Subtask run_main_py
[2024-11-08T17:36:16.988+0000] {task_command.py:415} INFO - Running <TaskInstance: daily_clothing_crawler.run_main_py manual__2024-11-08T17:31:15.692191+00:00 [running]> on host 58af73ec9de6
[2024-11-08T17:36:17.019+0000] {taskinstance.py:1660} INFO - Exporting env vars: AIRFLOW_CTX_DAG_OWNER='***' AIRFLOW_CTX_DAG_ID='daily_clothing_crawler' AIRFLOW_CTX_TASK_ID='run_main_py' AIRFLOW_CTX_EXECUTION_DATE='2024-11-08T17:31:15.692191+00:00' AIRFLOW_CTX_TRY_NUMBER='2' AIRFLOW_CTX_DAG_RUN_ID='manual__2024-11-08T17:31:15.692191+00:00'
[2024-11-08T17:36:17.020+0000] {subprocess.py:63} INFO - Tmp dir root location: /tmp
[2024-11-08T17:36:17.020+0000] {subprocess.py:75} INFO - Running command: ['/bin/bash', '-c', 'python3 app/main.py']
[2024-11-08T17:36:17.024+0000] {subprocess.py:86} INFO - Output:
[2024-11-08T17:36:17.077+0000] {subprocess.py:93} INFO - python3: can't open file 'app/main.py': [Errno 2] No such file or directory
[2024-11-08T17:36:17.078+0000] {subprocess.py:97} INFO - Command exited with return code 2
[2024-11-08T17:36:17.084+0000] {taskinstance.py:1935} ERROR - Task failed with exception
Traceback (most recent call last):
  File "/home/airflow/.local/lib/python3.8/site-packages/airflow/operators/bash.py", line 210, in execute
    raise AirflowException(
airflow.exceptions.AirflowException: Bash command failed. The command returned a non-zero exit code 2.
[2024-11-08T17:36:17.086+0000] {taskinstance.py:1398} INFO - Marking task as FAILED. dag_id=daily_clothing_crawler, task_id=run_main_py, execution_date=20241108T173115, start_date=20241108T173616, end_date=20241108T173617
[2024-11-08T17:36:17.092+0000] {standard_task_runner.py:104} ERROR - Failed to execute job 5 for task run_main_py (Bash command failed. The command returned a non-zero exit code 2.; 667)
[2024-11-08T17:36:17.104+0000] {local_task_job_runner.py:228} INFO - Task exited with return code 1
[2024-11-08T17:36:17.112+0000] {taskinstance.py:2776} INFO - 0 downstream tasks scheduled from follow-on schedule check
